<?xml version="1.0" encoding="UTF-8"?>
<testng-results skipped="0" failed="3" total="7" passed="4">
  <reporter-output>
  </reporter-output>
  <suite name="Default suite" duration-ms="7067" started-at="2015-05-17T20:49:00Z" finished-at="2015-05-17T20:49:07Z">
    <groups>
    </groups>
    <test name="Default test" duration-ms="7067" started-at="2015-05-17T20:49:00Z" finished-at="2015-05-17T20:49:07Z">
      <class name="UserTest">
        <test-method status="PASS" signature="setUp()[pri:0, instance:UserTest@2c6a3f77]" name="setUp" is-config="true" duration-ms="358" started-at="2015-05-17T23:49:00Z" finished-at="2015-05-17T23:49:01Z">
          <reporter-output>
          </reporter-output>
        </test-method> <!-- setUp -->
        <test-method status="PASS" signature="testAcceptFriendRequest()[pri:0, instance:UserTest@2c6a3f77]" name="testAcceptFriendRequest" duration-ms="4570" started-at="2015-05-17T23:49:01Z" finished-at="2015-05-17T23:49:05Z">
          <reporter-output>
          </reporter-output>
        </test-method> <!-- testAcceptFriendRequest -->
        <test-method status="FAIL" signature="testGetAllUserFriends()[pri:0, instance:UserTest@2c6a3f77]" name="testGetAllUserFriends" duration-ms="46" started-at="2015-05-17T23:49:05Z" finished-at="2015-05-17T23:49:05Z">
          <exception class="java.lang.AssertionError">
            <message>
              <![CDATA[null: lists don't have the same size expected [1] but found [0]]]>
            </message>
            <full-stacktrace>
              <![CDATA[java.lang.AssertionError: null: lists don't have the same size expected [1] but found [0]
	at org.testng.Assert.fail(Assert.java:94)
	at org.testng.Assert.failNotEquals(Assert.java:494)
	at org.testng.Assert.assertEquals(Assert.java:123)
	at org.testng.Assert.assertEquals(Assert.java:370)
	at org.testng.Assert.assertEquals(Assert.java:537)
	at org.testng.Assert.assertEquals(Assert.java:514)
	at UserTest.testGetAllUserFriends(UserTest.java:95)
	at sun.reflect.NativeMethodAccessorImpl.invoke0(Native Method)
	at sun.reflect.NativeMethodAccessorImpl.invoke(NativeMethodAccessorImpl.java:62)
	at sun.reflect.DelegatingMethodAccessorImpl.invoke(DelegatingMethodAccessorImpl.java:43)
	at java.lang.reflect.Method.invoke(Method.java:483)
	at org.testng.internal.MethodInvocationHelper.invokeMethod(MethodInvocationHelper.java:85)
	at org.testng.internal.Invoker.invokeMethod(Invoker.java:659)
	at org.testng.internal.Invoker.invokeTestMethod(Invoker.java:845)
	at org.testng.internal.Invoker.invokeTestMethods(Invoker.java:1153)
	at org.testng.internal.TestMethodWorker.invokeTestMethods(TestMethodWorker.java:124)
	at org.testng.internal.TestMethodWorker.run(TestMethodWorker.java:108)
	at org.testng.TestRunner.privateRun(TestRunner.java:771)
	at org.testng.TestRunner.run(TestRunner.java:621)
	at org.testng.SuiteRunner.runTest(SuiteRunner.java:352)
	at org.testng.SuiteRunner.runSequentially(SuiteRunner.java:347)
	at org.testng.SuiteRunner.privateRun(SuiteRunner.java:305)
	at org.testng.SuiteRunner.run(SuiteRunner.java:254)
	at org.testng.SuiteRunnerWorker.runSuite(SuiteRunnerWorker.java:52)
	at org.testng.SuiteRunnerWorker.run(SuiteRunnerWorker.java:86)
	at org.testng.TestNG.runSuitesSequentially(TestNG.java:1199)
	at org.testng.TestNG.runSuitesLocally(TestNG.java:1124)
	at org.testng.TestNG.run(TestNG.java:1032)
	at org.testng.remote.RemoteTestNG.run(RemoteTestNG.java:111)
	at org.testng.remote.RemoteTestNG.initAndRun(RemoteTestNG.java:204)
	at org.testng.remote.RemoteTestNG.main(RemoteTestNG.java:175)
]]>
            </full-stacktrace>
          </exception> <!-- java.lang.AssertionError -->
          <reporter-output>
          </reporter-output>
        </test-method> <!-- testGetAllUserFriends -->
        <test-method status="PASS" signature="testGetUser()[pri:0, instance:UserTest@2c6a3f77]" name="testGetUser" duration-ms="55" started-at="2015-05-17T23:49:05Z" finished-at="2015-05-17T23:49:06Z">
          <reporter-output>
          </reporter-output>
        </test-method> <!-- testGetUser -->
        <test-method status="PASS" signature="testGetUser2()[pri:0, instance:UserTest@2c6a3f77]" name="testGetUser2" duration-ms="39" started-at="2015-05-17T23:49:06Z" finished-at="2015-05-17T23:49:06Z">
          <reporter-output>
          </reporter-output>
        </test-method> <!-- testGetUser2 -->
        <test-method status="PASS" signature="testGetUserById()[pri:0, instance:UserTest@2c6a3f77]" name="testGetUserById" duration-ms="368" started-at="2015-05-17T23:49:06Z" finished-at="2015-05-17T23:49:06Z">
          <reporter-output>
          </reporter-output>
        </test-method> <!-- testGetUserById -->
        <test-method status="FAIL" signature="testRequestExistBefore()[pri:0, instance:UserTest@2c6a3f77]" name="testRequestExistBefore" duration-ms="32" started-at="2015-05-17T23:49:06Z" finished-at="2015-05-17T23:49:06Z">
          <exception class="java.lang.AssertionError">
            <message>
              <![CDATA[expected [true] but found [false]]]>
            </message>
            <full-stacktrace>
              <![CDATA[java.lang.AssertionError: expected [true] but found [false]
	at org.testng.Assert.fail(Assert.java:94)
	at org.testng.Assert.failNotEquals(Assert.java:494)
	at org.testng.Assert.assertTrue(Assert.java:42)
	at org.testng.Assert.assertTrue(Assert.java:52)
	at UserTest.testRequestExistBefore(UserTest.java:71)
	at sun.reflect.NativeMethodAccessorImpl.invoke0(Native Method)
	at sun.reflect.NativeMethodAccessorImpl.invoke(NativeMethodAccessorImpl.java:62)
	at sun.reflect.DelegatingMethodAccessorImpl.invoke(DelegatingMethodAccessorImpl.java:43)
	at java.lang.reflect.Method.invoke(Method.java:483)
	at org.testng.internal.MethodInvocationHelper.invokeMethod(MethodInvocationHelper.java:85)
	at org.testng.internal.Invoker.invokeMethod(Invoker.java:659)
	at org.testng.internal.Invoker.invokeTestMethod(Invoker.java:845)
	at org.testng.internal.Invoker.invokeTestMethods(Invoker.java:1153)
	at org.testng.internal.TestMethodWorker.invokeTestMethods(TestMethodWorker.java:124)
	at org.testng.internal.TestMethodWorker.run(TestMethodWorker.java:108)
	at org.testng.TestRunner.privateRun(TestRunner.java:771)
	at org.testng.TestRunner.run(TestRunner.java:621)
	at org.testng.SuiteRunner.runTest(SuiteRunner.java:352)
	at org.testng.SuiteRunner.runSequentially(SuiteRunner.java:347)
	at org.testng.SuiteRunner.privateRun(SuiteRunner.java:305)
	at org.testng.SuiteRunner.run(SuiteRunner.java:254)
	at org.testng.SuiteRunnerWorker.runSuite(SuiteRunnerWorker.java:52)
	at org.testng.SuiteRunnerWorker.run(SuiteRunnerWorker.java:86)
	at org.testng.TestNG.runSuitesSequentially(TestNG.java:1199)
	at org.testng.TestNG.runSuitesLocally(TestNG.java:1124)
	at org.testng.TestNG.run(TestNG.java:1032)
	at org.testng.remote.RemoteTestNG.run(RemoteTestNG.java:111)
	at org.testng.remote.RemoteTestNG.initAndRun(RemoteTestNG.java:204)
	at org.testng.remote.RemoteTestNG.main(RemoteTestNG.java:175)
]]>
            </full-stacktrace>
          </exception> <!-- java.lang.AssertionError -->
          <reporter-output>
          </reporter-output>
        </test-method> <!-- testRequestExistBefore -->
        <test-method status="FAIL" signature="testSendFriedRequest()[pri:0, instance:UserTest@2c6a3f77]" name="testSendFriedRequest" duration-ms="58" started-at="2015-05-17T23:49:06Z" finished-at="2015-05-17T23:49:06Z">
          <exception class="java.lang.AssertionError">
            <message>
              <![CDATA[expected [true] but found [false]]]>
            </message>
            <full-stacktrace>
              <![CDATA[java.lang.AssertionError: expected [true] but found [false]
	at org.testng.Assert.fail(Assert.java:94)
	at org.testng.Assert.failNotEquals(Assert.java:494)
	at org.testng.Assert.assertTrue(Assert.java:42)
	at org.testng.Assert.assertTrue(Assert.java:52)
	at UserTest.testSendFriedRequest(UserTest.java:65)
	at sun.reflect.NativeMethodAccessorImpl.invoke0(Native Method)
	at sun.reflect.NativeMethodAccessorImpl.invoke(NativeMethodAccessorImpl.java:62)
	at sun.reflect.DelegatingMethodAccessorImpl.invoke(DelegatingMethodAccessorImpl.java:43)
	at java.lang.reflect.Method.invoke(Method.java:483)
	at org.testng.internal.MethodInvocationHelper.invokeMethod(MethodInvocationHelper.java:85)
	at org.testng.internal.Invoker.invokeMethod(Invoker.java:659)
	at org.testng.internal.Invoker.invokeTestMethod(Invoker.java:845)
	at org.testng.internal.Invoker.invokeTestMethods(Invoker.java:1153)
	at org.testng.internal.TestMethodWorker.invokeTestMethods(TestMethodWorker.java:124)
	at org.testng.internal.TestMethodWorker.run(TestMethodWorker.java:108)
	at org.testng.TestRunner.privateRun(TestRunner.java:771)
	at org.testng.TestRunner.run(TestRunner.java:621)
	at org.testng.SuiteRunner.runTest(SuiteRunner.java:352)
	at org.testng.SuiteRunner.runSequentially(SuiteRunner.java:347)
	at org.testng.SuiteRunner.privateRun(SuiteRunner.java:305)
	at org.testng.SuiteRunner.run(SuiteRunner.java:254)
	at org.testng.SuiteRunnerWorker.runSuite(SuiteRunnerWorker.java:52)
	at org.testng.SuiteRunnerWorker.run(SuiteRunnerWorker.java:86)
	at org.testng.TestNG.runSuitesSequentially(TestNG.java:1199)
	at org.testng.TestNG.runSuitesLocally(TestNG.java:1124)
	at org.testng.TestNG.run(TestNG.java:1032)
	at org.testng.remote.RemoteTestNG.run(RemoteTestNG.java:111)
	at org.testng.remote.RemoteTestNG.initAndRun(RemoteTestNG.java:204)
	at org.testng.remote.RemoteTestNG.main(RemoteTestNG.java:175)
]]>
            </full-stacktrace>
          </exception> <!-- java.lang.AssertionError -->
          <reporter-output>
          </reporter-output>
        </test-method> <!-- testSendFriedRequest -->
        <test-method status="PASS" signature="tearDown()[pri:0, instance:UserTest@2c6a3f77]" name="tearDown" is-config="true" duration-ms="1401" started-at="2015-05-17T23:49:06Z" finished-at="2015-05-17T23:49:07Z">
          <reporter-output>
          </reporter-output>
        </test-method> <!-- tearDown -->
      </class> <!-- UserTest -->
    </test> <!-- Default test -->
  </suite> <!-- Default suite -->
</testng-results>
